<?xml version="1.0"?>

<robot name="scara">
    <gazebo>
        <plugin name="gazebo_ros_control" filename="libgazebo_ros_control.so">
            <robotNamespace>/scara</robotNamespace>
            <robotSimType>gazebo_ros_control/DefaultRobotHWSim</robotSimType>
        </plugin>
    </gazebo>
    <link name="base_link">
        <collision>
            <origin xyz="0 0 0" rpy="0 0 0"/>
            <geometry>
                <box size="0.5 0.5 0.3"/>
            </geometry>
        </collision>
        <visual>
            <geometry>
                <box size="0.5 0.5 0.3"/>
            </geometry>
        </visual>
        <inertial>
            <origin xyz="0 0 1" rpy="0 0 0"/>
            <mass value="1000"/>
            <inertia
                    ixx="1.0" ixy="0.0" ixz="0.0"
                    iyy="1.0" iyz="0.0"
                    izz="1.0"/>
        </inertial>
    </link>
    <link name="LinkOne">
        <visual>
            <geometry>
                <cylinder length="1" radius="0.2"/>
            </geometry>
            <origin rpy="0 0 0" xyz="0 0 0.5"></origin>
        </visual>
        <inertial>
            <origin xyz="0 0 1" rpy="0 0 0"/>
            <mass value="1"/>
            <inertia
                    ixx="1.0" ixy="0.0" ixz="0.0"
                    iyy="1.0" iyz="0.0"
                    izz="1.0"/>
        </inertial>
    </link>
    <joint name="baseToJOne" type="revolute">
        <axis xyz="0 0 1"/>
        3
        <limit effort="1000.0" lower="0.0" upper="6.2" velocity="0.5"/>
        <parent link="base_link"></parent>
        <child link="LinkOne"></child>
        <origin xyz="0 0 .15"></origin>
        <hardwareInterface>hardware_interface/EffortJointInterface</hardwareInterface>
    </joint>
    <link name="LinkTwo">
        <visual>
            <geometry>
                <cylinder length="1.4" radius="0.2"/>
            </geometry>
            <origin rpy="0 1.57075 0" xyz="0.3 0 1.2"></origin>
        </visual>
        <inertial>
            <origin xyz="0 0 1" rpy="0 0 0"/>
            <mass value="1"/>
            <inertia
                    ixx="1.0" ixy="0.0" ixz="0.0"
                    iyy="1.0" iyz="0.0"
                    izz="1.0"/>
        </inertial>
    </link>
    <joint name="JOneToJTwo" type="fixed">
        <parent link="LinkOne"></parent>
        <child link="LinkTwo"></child>
        <origin xyz="0.2 0 0"></origin>

    </joint>

    <link name="LinkThree">
        <visual>
            <geometry>
                <cylinder length="0.5" radius="0.2"/>
            </geometry>
            <origin rpy="0 0 0" xyz="0 0 -0.2"></origin>
        </visual>
        <inertial>
            <origin xyz="0 0 1" rpy="0 0 0"/>
            <mass value=".01"/>
            <inertia
                    ixx="1.0" ixy="0.0" ixz="0.0"
                    iyy="1.0" iyz="0.0"
                    izz="1.0"/>
        </inertial>
    </link>
    <joint name="JTwoToJThree" type="revolute">
        <axis xyz="0 0 1"/>
        <limit effort="1000.0" lower="-2.0" upper="2" velocity="0.5"/>
        <parent link="LinkTwo"></parent>
        <child link="LinkThree"></child>
        <origin xyz="1.2 0 1.4"></origin>
        <hardwareInterface>hardware_interface/EffortJointInterface</hardwareInterface>
    </joint>
    <link name="LinkFour">
        <visual>
            <geometry>
                <cylinder length="1" radius="0.2"/>
            </geometry>
            <origin rpy="0 1.57075 0" xyz="0 0 -0.2"></origin>
        </visual>
        <inertial>
            <origin xyz="0 0 1" rpy="0 0 0"/>
            <mass value="1"/>
            <inertia
                    ixx="1.0" ixy="0.0" ixz="0.0"
                    iyy="1.0" iyz="0.0"
                    izz="1.0"/>
        </inertial>
    </link>
    <joint name="JThreeToJFour" type="fixed">

        <parent link="LinkThree"></parent>
        <child link="LinkFour"></child>
        <origin xyz=".7 0 0"></origin>
    </joint>

    <link name="LinkFive">
        <visual>
            <geometry>
                <box size="0.5 0.5 0.5"/>
            </geometry>
            <origin rpy="0 3.14 0" xyz="0 0 0"></origin>
        </visual>
        <inertial>
            <origin xyz="0 0 1" rpy="0 0 0"/>
            <mass value=".01"/>
            <inertia
                    ixx="1.0" ixy="0.0" ixz="0.0"
                    iyy="1.0" iyz="0.0"
                    izz="1.0"/>
        </inertial>
    </link>
    <joint name="JFourToJFive" type="fixed">

        <parent link="LinkFour"></parent>
        <child link="LinkFive"></child>
        <origin xyz=".75 0 -.2"></origin>
    </joint>

    <link name="LinkSix">
        <visual>
            <geometry>
                <box size="0.3 0.3 0.3"/>
            </geometry>
            <origin rpy="0 0 0" xyz="0 0 0"></origin>
        </visual>
        <inertial>
            <origin xyz="0 0 1" rpy="0 0 0"/>
            <mass value=".01"/>
            <inertia
                    ixx="1.0" ixy="0.0" ixz="0.0"
                    iyy="1.0" iyz="0.0"
                    izz="1.0"/>
        </inertial>
    </link>
    <joint name="JFiveToJSix" type="prismatic">
        <limit effort="1000.0" lower="0.0" upper="1" velocity="0.5"/>
        <axis xyz="0 0 -1"/>
        <parent link="LinkFive"></parent>
        <child link="LinkSix"></child>
        <origin xyz="0 0 -.4"></origin>
        <hardwareInterface>hardware_interface/EffortJointInterface</hardwareInterface>
    </joint>

    <!-- Controller Stuff -->
    <transmission name="tran1">
        <type>transmission_interface/SimpleTransmission</type>
        <joint name="baseToJOne">
            <hardwareInterface>hardware_interface/EffortJointInterface</hardwareInterface>
        </joint>
        <actuator name="motor1">
            <hardwareInterface>hardware_interface/EffortJointInterface</hardwareInterface>
            <mechanicalReduction>1</mechanicalReduction>
        </actuator>
    </transmission>

    <transmission name="tran2">
        <type>transmission_interface/SimpleTransmission</type>
        <joint name="JTwoToJThree">
            <hardwareInterface>hardware_interface/EffortJointInterface</hardwareInterface>
        </joint>
        <actuator name="motor2">
            <hardwareInterface>hardware_interface/EffortJointInterface</hardwareInterface>
            <mechanicalReduction>1</mechanicalReduction>
        </actuator>
    </transmission>

    <transmission name="tran3">
        <type>transmission_interface/SimpleTransmission</type>
        <joint name="JFiveToJSix">
            <hardwareInterface>hardware_interface/EffortJointInterface</hardwareInterface>
        </joint>
        <actuator name="motor3">
            <hardwareInterface>hardware_interface/EffortJointInterface</hardwareInterface>
            <mechanicalReduction>1</mechanicalReduction>
        </actuator>
    </transmission>

</robot>